Workbook

Sheet 테스트 세트
A1: # | B1: 칸 | C1: 연령 | D1: URL | E1: 제목 | F1: 채널 | G1: 가라벨 / 이유 (검색 기준) | H1: 상태 | I1: 정답지 추천 | J1: 확정 라벨 (내가 찍음) | K1: 확정 판정 | L1: 밝힘 문구 있음? | M1: 비고
A2: 1 | B2: 틴 봐도 됨 (Lens) | C2: 틴 | D2: https://www.youtube.com/watch?v=_OxuxhHF1WI | E2: Last Chance to Win This $30,000 Tesla Model X, Giveaway Ends Tonight | F2: Auto Auction Rebuilds | G2: URG, RICH | H2: 확인, 데모 1 | I2: 정답지
A3: 2 | B3: 틴 봐도 됨 (Lens) | C3: 틴 | D3: https://www.youtube.com/watch?v=H4RZKSOCQpE | E3: Supercharged Camaro Giveaway ENDS TONIGHT | F3: RestoMods | G3: URG, RICH | H3: 확인
A4: 3 | B4: 틴 봐도 됨 (Lens) | C4: 틴 | D4: https://www.youtube.com/watch?v=YjIA7HJXFg0 | E4: My 14-Day Detox Results w/ Skinny Teatox | F4: TheBrilliantBeauty | G4: BODY, AD는 밝힘 문구 확인 후 | H4: 확인, 데모 2 | I4: 정답지
A5: 4 | B5: 틴 봐도 됨 (Lens) | C5: 틴 | D5: https://www.youtube.com/watch?v=HgjRJAh9kME | E5: Kourtney Kardashian Flat Tummy Tea Review | F5: Jessica Carroll | G5: BODY, AD (밝힘 없음 메모, 확인 필요) | H5: 확인, 데모 3 후보
A6: 5 | B6: 틴 봐도 됨 (Lens) | C6: 틴 | D6: https://www.youtube.com/watch?v=TVYv8TQjUiU | E6: HONEST REVIEW 28 DAYS DETOX FLAT TUMMY TEA BEFORE AND AFTER | F6: Charmbody254 | G6: BODY, AD, PROOF | H6: 확인
A7: 6 | B7: 틴 봐도 됨 (Lens) | C7: 틴 | D7: https://www.youtube.com/watch?v=tm9Xfv6wpN4 | E7: I TRIED APPLE CIDER VINEGAR FOR 1 WEEK, I'M SHOOK | F7: The Daily Student | G7: BODY, CLICK | H7: 확인
A8: 7 | B8: 틴 봐도 됨 (Lens) | C8: 틴 | D8: https://www.youtube.com/watch?v=NT3I2bhm1Ek | E8: I tried Korean skincare for 6 months, the results are shocking! | F8: BILLIE BLONDE | G8: BODY, AD, CLICK | H8: 확인
A9: 8 | B9: 틴 봐도 됨 (Lens) | C9: 틴 | D9: https://www.youtube.com/watch?v=Blzl_nifKYg | E9: I bought EVERY VIRAL Tik Tok makeup product so you don't have to! | F9: Manny Mua | G9: PROOF, AD | H9: 확인
A10: 9 | B10: 틴 봐도 됨 (Lens) | C10: 틴 | D10: https://www.youtube.com/watch?v=N8EYO-GIdTs | E10: Week in My Life as A Humble 22 y/o Multi Millionaire | F10: DESIRICHKID | G10: COMPARE, 설명란에 코칭 판매 | H10: 확인
A11: 10 | B11: 틴 봐도 됨 (Lens) | C11: 틴 | D11: https://www.youtube.com/watch?v=h5BROsH6LYE | E11: How I've made $10K a month online since I was 15 | F11: Taylor Rankine | G11: RICH, COMPARE | H11: 확인
A12: 11 | B12: 틴 주의 (Lens + 부모 표시) | C12: 틴 | D12: https://www.youtube.com/watch?v=3kdnLb-fdrY | E12: How I lost 20 pounds in 2 weeks on a low budget | F12: Nkemamaka Ike | G12: 강한 체중 수치 + 기간, 밝힘 없음 | H12: 확인 | I12: 정답지
A13: 12 | B13: 틴 주의 (Lens + 부모 표시) | C13: 틴 | D13: https://www.youtube.com/watch?v=2VTb1eVw7Cg | E13: I tried the 20lbs in 2 weeks DANCE WORKOUT and it WORKED! | F13: Jazz Rose | G13: 강한 체중 주장 + 설명란이 링크·할인코드 | H13: 확인
A14: 13 | B14: 틴 주의 (Lens + 부모 표시) | C14: 틴 | D14: https://www.youtube.com/watch?v=VGWnU-Lqrxc | E14: WHAT I EAT IN A DAY, Secrets to staying slim! | F14: Laura Blair | G14: 식단 제한을 동경하게 하는 프레임 | H14: 확인
A15: 14 | B15: 틴 차단 | C15: 틴 | D15: https://www.youtube.com/watch?v=RkSXs2WToDY | E15: The BIGGEST Operation Case Opening ($10,000) | F15: DrewUnboxing | G15: 도박형: 실제 돈 룻박스 | H15: 확인, 데모 후보 | I15: 정답지
A16: 15 | B16: 틴 차단 | C16: 틴 | D16: https://www.youtube.com/watch?v=sxUFgzwgWhc | E16: BEST CS2 GAMBLING SITES OF 2025, Get Free CSGO Skins, Promo Code | F16: veyzix | G16: 도박형: 스킨 도박 사이트 추천코드 5개, 페이지 18+ | H16: 확인, 데모 후보
A17: 16 | B17: 틴 차단 | C17: 틴 | D17: https://www.youtube.com/watch?v=sePMRp_CF68 | E17: 8 MINUTES OF STREET FIGHTS & HOOD FIGHTS 2025 | F17: MOTO FURY 2 | G17: 폭력 미화 | H17: 확인
A18: 17 | B18: 틴 차단 | C18: 틴 | D18: https://www.youtube.com/watch?v=9ivV1sbd9cs | E18: HOOD FIGHTS 2024 & STREET FIGHTS, SCHOOL FIGHTS, ROAD RAGE | F18: MOTO FURY 2 | G18: 폭력 미화, 제목에 school fights | H18: 확인, 데모 후보 | I18: 정답지
A19: 18 | B19: 틴 차단 | C19: 틴 | D19: https://www.youtube.com/watch?v=9ZcmzB9ToZo | E19: Vape Trick Tutorial, How to: Jellyfish | F19: vAustinL | G19: 약물·흡연 미화 | H19: 확인
A20: 19 | B20: 틴 차단 | C20: 틴 | D20: https://www.youtube.com/watch?v=IXR7ZAXA5oU | E20: My First Time Getting Drunk.. | F20: GeologyshiXtra | G20: 음주 미화 | H20: 확인
A21: 20 | B21: 틴 차단 | C21: 틴 | D21: https://www.youtube.com/watch?v=CP1bEZXk34I | E21: I Tried SARMS at 16 and Here's What Happened | F21: Anthony Mantello | G21: 미승인 약물 + 보조제 할인코드 | H21: 확인
A22: 21 | B22: 틴 차단 | C22: 틴 | D22: https://www.youtube.com/watch?v=I3xzzAN1-z4 | E22: AKC F-16 OTF Automatic Knife Review, A fun cheapish switchblade | F22: Advanced Knife Bro | G22: 무기 + 구매 링크 | H22: 확인
A23: 22 | B23: 틴 차단 | C23: 틴 | D23: https://www.youtube.com/watch?v=MIrjg_jPD88 | E23: Master KARAMBIT Flipping in Minutes! Great for Beginners | F23: Kali Center | G23: 무기 + 스토어 링크 | H23: 확인
A24: 23 | B24: 틴 차단 | C24: 틴 | D24: https://www.youtube.com/watch?v=tL49cpCfW00 | E24: Best FREE Telegram Trading Signal Group, HIGH Profits 2026 | F24: CryptoNinjas | G24: 사적 연락 유도: t.me 그룹 + private group | H24: 확인, 데모 후보
A25: 24 | B25: 틴 차단 | C25: 틴 | D25: https://www.youtube.com/watch?v=vntmLCH6M1w | E25: Andrew Tate SCHOOLS Modern Women | F25: whatever Clips | G25: 매노스피어 클립 | H25: 확인
A26: 25 | B26: 틴 차단 | C26: 틴 | D26: https://www.youtube.com/watch?v=Vl6BwGkhH9I | E26: STREET TAKEOVER IS ACTIVE ALL NIGHT! SIDESHOW TAKEOVER!! | F26: DStreet | G26: 위험 운전 미화 | H26: 확인
A27: 26 | B27: 키즈 봐도 됨 | C27: 키즈 | D27: https://www.youtube.com/watch?v=wfnsRi8Jgdw | E27: The Great Elephant Toothpaste Experiment! | F27: SciShow Kids | G27: 신뢰 채널, 수법 없음 | H27: 확인, 6:23 | I27: 정답지
A28: 27 | B28: 키즈 봐도 됨 | C28: 키즈 | D28: https://www.youtube.com/watch?v=0Qmgdz9E47s | E28: The Power of Sunlight! Science Project for Kids | F28: SciShow Kids | G28: 신뢰 채널, 수법 없음 | H28: 확인
A29: 28 | B29: 키즈 봐도 됨 | C29: 키즈 | D29: https://www.youtube.com/watch?v=GkBWcJBxSMs | E29: Let's Make Slime! | F29: SciShow Kids | G29: 신뢰 채널, 수법 없음 | H29: 검색만
A30: 29 | B30: 키즈 봐도 됨 | C30: 키즈 | D30: https://www.youtube.com/watch?v=a-SPYPAedCA | E30: Unpoppable Bubbles! | F30: SciShow Kids | G30: 신뢰 채널, 수법 없음 | H30: 검색만
A31: 30 | B31: 키즈 봐도 됨 | C31: 키즈 | D31: https://www.youtube.com/watch?v=nmh5ot2F6gM | E31: Super Strange Animals, Super Animals Full Episode | F31: Nat Geo Kids | G31: 신뢰 채널, 수법 없음 | H31: 확인
A32: 31 | B32: 키즈 봐도 됨 | C32: 키즈 | D32: https://www.youtube.com/watch?v=GULXtdoLgpQ | E32: LEGO Ideas Medieval Blacksmith 21325 Designer Video | F32: LEGO | G32: 신뢰 채널, 수법 없음 | H32: 확인
A33: 32 | B33: 키즈 봐도 됨 | C33: 키즈 | D33: https://www.youtube.com/watch?v=HcItfU1zwqE | E33: LEGO Creator Expert Fiat 500 Designer Video | F33: LEGO | G33: 신뢰 채널, 수법 없음 | H33: 확인
A34: 33 | B34: 키즈 승인 필요 | C34: 키즈 | D34: https://www.youtube.com/watch?v=DBwGvKFqBSo | E34: COMBO PANDA TOYS ARE HERE! Ryan's World Toy Shopping at Walmart and Unboxing | F34: Combo Panda | G34: 언박싱 + 자사 장난감 쇼핑 | H34: 확인 | I34: 정답지
A35: 34 | B35: 키즈 승인 필요 | C35: 키즈 | D35: https://www.youtube.com/watch?v=2uNNqelTWcs | E35: ULTRA RARE RYAN'S WORLD Mystery Figure?! Surprise Toy Unboxing | F35: Channel TOYS Canada | G35: 블라인드백 '희귀템 나올까' 훅 | H35: 확인
A36: 35 | B36: 키즈 승인 필요 | C36: 키즈 | D36: https://www.youtube.com/watch?v=HHugwVWVN-U | E36: Vlad and Niki Crazy Rocketship Playset Unboxing & Review | F36: TTPM Toy Reviews | G36: 상업 장난감 리뷰 채널 | H36: 확인
A37: 36 | B37: 키즈 승인 필요 | C37: 키즈 | D37: https://www.youtube.com/watch?v=mBey7fGYeQ0 | E37: You Won't Believe This Lego Pokemon Build! | F37: BKHBRICKS | G37: 주제는 OK, 제목이 낚시 | H37: 확인
A38: 37 | B38: 키즈 승인 필요 | C38: 키즈 | D38: https://www.youtube.com/watch?v=_p-10Dnytgw | E38: School/Science Project, Water Wheel, Tinker Crate by KiwiCo | F38: Matt Creationz | G38: 제품명 노출, 밝힘 없음 | H38: 확인
A39: 38 | B39: 키즈 숨김 | C39: 키즈 | D39: https://www.youtube.com/watch?v=ynLw9MGPicw | E39: All Jumpscares / SCARY Moments in Outlast & DLC | F39: DemonBlade Husky | G39: 리얼 호러 게임 | H39: 확인, 데모 후보 | I39: 정답지
A40: 39 | B40: 키즈 숨김 | C40: 키즈 | D40: https://www.youtube.com/watch?v=y7TJQTqGNqA | E40: THE 35 SCARIEST MOMENTS IN Dead By Daylight HISTORY! | F40: Dead By Daylight Overdose | G40: 리얼 호러 게임 | H40: 확인
...

Sheet 칸별 집계
A1: 칸 | B1: 개수 | C1: 정답지 추천 | D1: 확정 판정 입력됨
A2: 틴 봐도 됨 (Lens) | B2: =COUNTIF('테스트 세트'!$B$2:$B$57,A2) -> 10 | C2: =COUNTIFS('테스트 세트'!$B$2:$B$57,A2,'테스트 세트'!$I$2:$I$57,"정답지") -> 2 | D2: =COUNTIFS('테스트 세트'!$B$2:$B$57,A2,'테스트 세트'!$K$2:$K$57,"<>") -> 0
A3: 틴 주의 (Lens + 부모 표시) | B3: =COUNTIF('테스트 세트'!$B$2:$B$57,A3) -> 3 | C3: =COUNTIFS('테스트 세트'!$B$2:$B$57,A3,'테스트 세트'!$I$2:$I$57,"정답지") -> 1 | D3: =COUNTIFS('테스트 세트'!$B$2:$B$57,A3,'테스트 세트'!$K$2:$K$57,"<>") -> 0
A4: 틴 차단 | B4: =COUNTIF('테스트 세트'!$B$2:$B$57,A4) -> 12 | C4: =COUNTIFS('테스트 세트'!$B$2:$B$57,A4,'테스트 세트'!$I$2:$I$57,"정답지") -> 2 | D4: =COUNTIFS('테스트 세트'!$B$2:$B$57,A4,'테스트 세트'!$K$2:$K$57,"<>") -> 0
A5: 키즈 봐도 됨 | B5: =COUNTIF('테스트 세트'!$B$2:$B$57,A5) -> 7 | C5: =COUNTIFS('테스트 세트'!$B$2:$B$57,A5,'테스트 세트'!$I$2:$I$57,"정답지") -> 1 | D5: =COUNTIFS('테스트 세트'!$B$2:$B$57,A5,'테스트 세트'!$K$2:$K$57,"<>") -> 0
A6: 키즈 승인 필요 | B6: =COUNTIF('테스트 세트'!$B$2:$B$57,A6) -> 5 | C6: =COUNTIFS('테스트 세트'!$B$2:$B$57,A6,'테스트 세트'!$I$2:$I$57,"정답지") -> 1 | D6: =COUNTIFS('테스트 세트'!$B$2:$B$57,A6,'테스트 세트'!$K$2:$K$57,"<>") -> 0
A7: 키즈 숨김 | B7: =COUNTIF('테스트 세트'!$B$2:$B$57,A7) -> 12 | C7: =COUNTIFS('테스트 세트'!$B$2:$B$57,A7,'테스트 세트'!$I$2:$I$57,"정답지") -> 2 | D7: =COUNTIFS('테스트 세트'!$B$2:$B$57,A7,'테스트 세트'!$K$2:$K$57,"<>") -> 0
A8: 오탐 테스트 | B8: =COUNTIF('테스트 세트'!$B$2:$B$57,A8) -> 7 | C8: =COUNTIFS('테스트 세트'!$B$2:$B$57,A8,'테스트 세트'!$I$2:$I$57,"정답지") -> 2 | D8: =COUNTIFS('테스트 세트'!$B$2:$B$57,A8,'테스트 세트'!$K$2:$K$57,"<>") -> 0
A9: 합계 | B9: =SUM(B2:B8) -> 56 | C9: =SUM(C2:C8) -> 11 | D9: =SUM(D2:D8) -> 0
